{"uuid": "ff002c04-2c77-496c-8f40-7af953facddf", "children": ["508f13be-ccc4-4038-868b-fc465717f562"], "befores": [{"name": "_Module__pytest_setup_module", "status": "passed", "start": 1618903890656, "stop": 1618903890656}], "afters": [{"name": "_Module__pytest_setup_module::0", "status": "broken", "statusDetails": {"message": "pymysql.err.InternalError: (1003, 'Transaction error, need to rollback.')\n", "trace": "  File \"C:\\Users\\chenping\\PycharmProjects\\apitest\\venv\\lib\\site-packages\\allure_commons\\_allure.py\", line 185, in __call__\n    return self._fixture_function(*args, **kwargs)\n  File \"C:\\Users\\chenping\\PycharmProjects\\apitest\\venv\\lib\\site-packages\\_pytest\\fixtures.py\", line 800, in _teardown_yield_fixture\n    next(it)\n  File \"C:\\Users\\chenping\\PycharmProjects\\apitest\\venv\\lib\\site-packages\\_pytest\\python.py\", line 474, in xunit_setup_module_fixture\n    _call_with_optional_argument(teardown_module, request.module)\n  File \"C:\\Users\\chenping\\PycharmProjects\\apitest\\venv\\lib\\site-packages\\_pytest\\python.py\", line 634, in _call_with_optional_argument\n    func()\n  File \"C:\\Users\\chenping\\PycharmProjects\\apitest\\testcase\\Loginapi\\Change_MobilePhone_test.py\", line 102, in teardown_module\n    PyMySQL().mysqlupdate('customer',{'cust_id':Change_MobilePhone.initparams['custid']},{'cust_mobile':Change_MobilePhone.initparams['mobile_phone']})\n  File \"C:\\Users\\chenping\\PycharmProjects\\apitest\\utils\\pysql.py\", line 78, in mysqlupdate\n    self.conn.commit()\n  File \"C:\\Users\\chenping\\PycharmProjects\\apitest\\venv\\lib\\site-packages\\pymysql\\connections.py\", line 420, in commit\n    self._read_ok_packet()\n  File \"C:\\Users\\chenping\\PycharmProjects\\apitest\\venv\\lib\\site-packages\\pymysql\\connections.py\", line 394, in _read_ok_packet\n    pkt = self._read_packet()\n  File \"C:\\Users\\chenping\\PycharmProjects\\apitest\\venv\\lib\\site-packages\\pymysql\\connections.py\", line 684, in _read_packet\n    packet.check_error()\n  File \"C:\\Users\\chenping\\PycharmProjects\\apitest\\venv\\lib\\site-packages\\pymysql\\protocol.py\", line 220, in check_error\n    err.raise_mysql_exception(self._data)\n  File \"C:\\Users\\chenping\\PycharmProjects\\apitest\\venv\\lib\\site-packages\\pymysql\\err.py\", line 109, in raise_mysql_exception\n    raise errorclass(errno, errval)\n"}, "start": 1618903890690, "stop": 1618903890712}], "start": 1618903890656, "stop": 1618903890712}