{"uuid": "c629835a-8b0b-4c47-a521-bd3401889a17", "children": ["6f2f1ce5-e84b-44d6-998f-0f94215ef649", "a1b3ac6d-0775-4286-b423-d9386fba95b1", "280afbbb-0b0c-4126-ba0e-b0540083a449", "e016622f-5ebc-498d-a6cb-aefab9446c6d", "a9ca8e0e-4603-48e3-9368-7d2298055047", "a00c751f-82eb-4ce6-b55b-16e11a3d3116", "c21cd316-31bc-4d4d-8af4-c09ab9f450d8", "f35cbadc-c079-44f4-af4d-cf42c185c1d6", "a54022d6-f3b1-4ff7-8c54-450e1e317ab5", "6493e460-518f-4feb-b28a-a7cb3caacd66", "2ed94208-21d1-4621-8afa-052b0ec8128e", "d436b58f-3c20-4883-99b3-449692e667cf"], "befores": [{"name": "_Module__pytest_setup_module", "status": "passed", "start": 1618903839650, "stop": 1618903839650}], "afters": [{"name": "_Module__pytest_setup_module::0", "status": "broken", "statusDetails": {"message": "pymysql.err.InternalError: (1003, 'Transaction error, need to rollback.')\n", "trace": "  File \"C:\\Users\\chenping\\PycharmProjects\\apitest\\venv\\lib\\site-packages\\allure_commons\\_allure.py\", line 185, in __call__\n    return self._fixture_function(*args, **kwargs)\n  File \"C:\\Users\\chenping\\PycharmProjects\\apitest\\venv\\lib\\site-packages\\_pytest\\fixtures.py\", line 800, in _teardown_yield_fixture\n    next(it)\n  File \"C:\\Users\\chenping\\PycharmProjects\\apitest\\venv\\lib\\site-packages\\_pytest\\python.py\", line 474, in xunit_setup_module_fixture\n    _call_with_optional_argument(teardown_module, request.module)\n  File \"C:\\Users\\chenping\\PycharmProjects\\apitest\\venv\\lib\\site-packages\\_pytest\\python.py\", line 634, in _call_with_optional_argument\n    func()\n  File \"C:\\Users\\chenping\\PycharmProjects\\apitest\\testcase\\Loginapi\\Change_MobilePhone_test.py\", line 102, in teardown_module\n    PyMySQL().mysqlupdate('customer',{'cust_id':Change_MobilePhone.initparams['custid']},{'cust_mobile':Change_MobilePhone.initparams['mobile_phone']})\n  File \"C:\\Users\\chenping\\PycharmProjects\\apitest\\utils\\pysql.py\", line 78, in mysqlupdate\n    self.conn.commit()\n  File \"C:\\Users\\chenping\\PycharmProjects\\apitest\\venv\\lib\\site-packages\\pymysql\\connections.py\", line 420, in commit\n    self._read_ok_packet()\n  File \"C:\\Users\\chenping\\PycharmProjects\\apitest\\venv\\lib\\site-packages\\pymysql\\connections.py\", line 394, in _read_ok_packet\n    pkt = self._read_packet()\n  File \"C:\\Users\\chenping\\PycharmProjects\\apitest\\venv\\lib\\site-packages\\pymysql\\connections.py\", line 684, in _read_packet\n    packet.check_error()\n  File \"C:\\Users\\chenping\\PycharmProjects\\apitest\\venv\\lib\\site-packages\\pymysql\\protocol.py\", line 220, in check_error\n    err.raise_mysql_exception(self._data)\n  File \"C:\\Users\\chenping\\PycharmProjects\\apitest\\venv\\lib\\site-packages\\pymysql\\err.py\", line 109, in raise_mysql_exception\n    raise errorclass(errno, errval)\n"}, "start": 1618903880385, "stop": 1618903880486}], "start": 1618903839650, "stop": 1618903880486}