{"uuid": "8312ad88-7aa3-42bd-ad16-d665c3a5a740", "children": ["b9fa3d01-92cb-40d5-8491-21ce5ebdecdd"], "befores": [{"name": "_Module__pytest_setup_module", "status": "broken", "statusDetails": {"message": "pymysql.err.InternalError: (1003, 'Transaction error, need to rollback.')\n", "trace": "  File \"C:\\Users\\chenping\\PycharmProjects\\apitest\\venv\\lib\\site-packages\\pluggy\\callers.py\", line 187, in _multicall\n    res = hook_impl.function(*args)\n  File \"C:\\Users\\chenping\\PycharmProjects\\apitest\\venv\\lib\\site-packages\\_pytest\\fixtures.py\", line 964, in pytest_fixture_setup\n    result = call_fixture_func(fixturefunc, request, kwargs)\n  File \"C:\\Users\\chenping\\PycharmProjects\\apitest\\venv\\lib\\site-packages\\_pytest\\fixtures.py\", line 788, in call_fixture_func\n    res = next(it)\n  File \"C:\\Users\\chenping\\PycharmProjects\\apitest\\venv\\lib\\site-packages\\_pytest\\python.py\", line 471, in xunit_setup_module_fixture\n    _call_with_optional_argument(setup_module, request.module)\n  File \"C:\\Users\\chenping\\PycharmProjects\\apitest\\venv\\lib\\site-packages\\_pytest\\python.py\", line 634, in _call_with_optional_argument\n    func()\n  File \"C:\\Users\\chenping\\PycharmProjects\\apitest\\testcase\\Loginapi\\Check_Sms_Vcode_test.py\", line 86, in setup_module\n    PyMySQL().mysqlinsert(\"customer_verify_email\",insert_data)\n  File \"C:\\Users\\chenping\\PycharmProjects\\apitest\\utils\\pysql.py\", line 128, in mysqlinsert\n    self.conn.commit()\n  File \"C:\\Users\\chenping\\PycharmProjects\\apitest\\venv\\lib\\site-packages\\pymysql\\connections.py\", line 420, in commit\n    self._read_ok_packet()\n  File \"C:\\Users\\chenping\\PycharmProjects\\apitest\\venv\\lib\\site-packages\\pymysql\\connections.py\", line 394, in _read_ok_packet\n    pkt = self._read_packet()\n  File \"C:\\Users\\chenping\\PycharmProjects\\apitest\\venv\\lib\\site-packages\\pymysql\\connections.py\", line 684, in _read_packet\n    packet.check_error()\n  File \"C:\\Users\\chenping\\PycharmProjects\\apitest\\venv\\lib\\site-packages\\pymysql\\protocol.py\", line 220, in check_error\n    err.raise_mysql_exception(self._data)\n  File \"C:\\Users\\chenping\\PycharmProjects\\apitest\\venv\\lib\\site-packages\\pymysql\\err.py\", line 109, in raise_mysql_exception\n    raise errorclass(errno, errval)\n"}, "start": 1619590198375, "stop": 1619590198398}], "start": 1619590198375, "stop": 1619590198586}