{"uuid": "08efc20d-d370-4dd5-830e-588a837dc4e0", "children": ["8ccf75f6-3ba1-4737-96e9-223173d497c1", "6a5ba004-b7aa-4409-bea6-7aedc6f1ed53", "3aaf943f-0237-4846-9e72-1407d24d221b", "735f5385-ac1e-4adb-a475-9cdab0065e90", "7405bdd2-ab3a-4420-b026-2e0d13732be5", "6b606da8-2d9a-4063-a3cb-5cc64d444e41", "6a3d1a24-f5d7-4914-9471-75f09c10e62c", "84509298-bb4a-4879-96be-7d60c29af316", "dbaa0c74-ae53-4fa0-8039-8d3f647762b3"], "befores": [{"name": "_Module__pytest_setup_module", "status": "broken", "statusDetails": {"message": "pymysql.err.InternalError: (1003, 'Transaction error, need to rollback.')\n", "trace": "  File \"C:\\Users\\chenping\\PycharmProjects\\apitest\\venv\\lib\\site-packages\\pluggy\\callers.py\", line 187, in _multicall\n    res = hook_impl.function(*args)\n  File \"C:\\Users\\chenping\\PycharmProjects\\apitest\\venv\\lib\\site-packages\\_pytest\\fixtures.py\", line 964, in pytest_fixture_setup\n    result = call_fixture_func(fixturefunc, request, kwargs)\n  File \"C:\\Users\\chenping\\PycharmProjects\\apitest\\venv\\lib\\site-packages\\_pytest\\fixtures.py\", line 788, in call_fixture_func\n    res = next(it)\n  File \"C:\\Users\\chenping\\PycharmProjects\\apitest\\venv\\lib\\site-packages\\_pytest\\python.py\", line 471, in xunit_setup_module_fixture\n    _call_with_optional_argument(setup_module, request.module)\n  File \"C:\\Users\\chenping\\PycharmProjects\\apitest\\venv\\lib\\site-packages\\_pytest\\python.py\", line 634, in _call_with_optional_argument\n    func()\n  File \"C:\\Users\\chenping\\PycharmProjects\\apitest\\testcase\\Loginapi\\Check_Sms_Vcode_test.py\", line 86, in setup_module\n    PyMySQL().mysqlinsert(\"customer_verify_email\",insert_data)\n  File \"C:\\Users\\chenping\\PycharmProjects\\apitest\\utils\\pysql.py\", line 128, in mysqlinsert\n    self.conn.commit()\n  File \"C:\\Users\\chenping\\PycharmProjects\\apitest\\venv\\lib\\site-packages\\pymysql\\connections.py\", line 420, in commit\n    self._read_ok_packet()\n  File \"C:\\Users\\chenping\\PycharmProjects\\apitest\\venv\\lib\\site-packages\\pymysql\\connections.py\", line 394, in _read_ok_packet\n    pkt = self._read_packet()\n  File \"C:\\Users\\chenping\\PycharmProjects\\apitest\\venv\\lib\\site-packages\\pymysql\\connections.py\", line 684, in _read_packet\n    packet.check_error()\n  File \"C:\\Users\\chenping\\PycharmProjects\\apitest\\venv\\lib\\site-packages\\pymysql\\protocol.py\", line 220, in check_error\n    err.raise_mysql_exception(self._data)\n  File \"C:\\Users\\chenping\\PycharmProjects\\apitest\\venv\\lib\\site-packages\\pymysql\\err.py\", line 109, in raise_mysql_exception\n    raise errorclass(errno, errval)\n"}, "start": 1619590146182, "stop": 1619590146223}, {"name": "_Module__pytest_setup_module", "status": "broken", "statusDetails": {"message": "pymysql.err.InternalError: (1003, 'Transaction error, need to rollback.')\n", "trace": "  File \"C:\\Users\\chenping\\PycharmProjects\\apitest\\venv\\lib\\site-packages\\pluggy\\callers.py\", line 187, in _multicall\n    res = hook_impl.function(*args)\n  File \"C:\\Users\\chenping\\PycharmProjects\\apitest\\venv\\lib\\site-packages\\_pytest\\fixtures.py\", line 964, in pytest_fixture_setup\n    result = call_fixture_func(fixturefunc, request, kwargs)\n  File \"C:\\Users\\chenping\\PycharmProjects\\apitest\\venv\\lib\\site-packages\\_pytest\\fixtures.py\", line 788, in call_fixture_func\n    res = next(it)\n  File \"C:\\Users\\chenping\\PycharmProjects\\apitest\\venv\\lib\\site-packages\\_pytest\\python.py\", line 471, in xunit_setup_module_fixture\n    _call_with_optional_argument(setup_module, request.module)\n  File \"C:\\Users\\chenping\\PycharmProjects\\apitest\\venv\\lib\\site-packages\\_pytest\\python.py\", line 634, in _call_with_optional_argument\n    func()\n  File \"C:\\Users\\chenping\\PycharmProjects\\apitest\\testcase\\Loginapi\\Check_Sms_Vcode_test.py\", line 86, in setup_module\n    PyMySQL().mysqlinsert(\"customer_verify_email\",insert_data)\n  File \"C:\\Users\\chenping\\PycharmProjects\\apitest\\utils\\pysql.py\", line 128, in mysqlinsert\n    self.conn.commit()\n  File \"C:\\Users\\chenping\\PycharmProjects\\apitest\\venv\\lib\\site-packages\\pymysql\\connections.py\", line 420, in commit\n    self._read_ok_packet()\n  File \"C:\\Users\\chenping\\PycharmProjects\\apitest\\venv\\lib\\site-packages\\pymysql\\connections.py\", line 394, in _read_ok_packet\n    pkt = self._read_packet()\n  File \"C:\\Users\\chenping\\PycharmProjects\\apitest\\venv\\lib\\site-packages\\pymysql\\connections.py\", line 684, in _read_packet\n    packet.check_error()\n  File \"C:\\Users\\chenping\\PycharmProjects\\apitest\\venv\\lib\\site-packages\\pymysql\\protocol.py\", line 220, in check_error\n    err.raise_mysql_exception(self._data)\n  File \"C:\\Users\\chenping\\PycharmProjects\\apitest\\venv\\lib\\site-packages\\pymysql\\err.py\", line 109, in raise_mysql_exception\n    raise errorclass(errno, errval)\n"}, "start": 1619590156605, "stop": 1619590156625}, {"name": "_Module__pytest_setup_module", "status": "broken", "statusDetails": {"message": "pymysql.err.InternalError: (1003, 'Transaction error, need to rollback.')\n", "trace": "  File \"C:\\Users\\chenping\\PycharmProjects\\apitest\\venv\\lib\\site-packages\\pluggy\\callers.py\", line 187, in _multicall\n    res = hook_impl.function(*args)\n  File \"C:\\Users\\chenping\\PycharmProjects\\apitest\\venv\\lib\\site-packages\\_pytest\\fixtures.py\", line 964, in pytest_fixture_setup\n    result = call_fixture_func(fixturefunc, request, kwargs)\n  File \"C:\\Users\\chenping\\PycharmProjects\\apitest\\venv\\lib\\site-packages\\_pytest\\fixtures.py\", line 788, in call_fixture_func\n    res = next(it)\n  File \"C:\\Users\\chenping\\PycharmProjects\\apitest\\venv\\lib\\site-packages\\_pytest\\python.py\", line 471, in xunit_setup_module_fixture\n    _call_with_optional_argument(setup_module, request.module)\n  File \"C:\\Users\\chenping\\PycharmProjects\\apitest\\venv\\lib\\site-packages\\_pytest\\python.py\", line 634, in _call_with_optional_argument\n    func()\n  File \"C:\\Users\\chenping\\PycharmProjects\\apitest\\testcase\\Loginapi\\Check_Sms_Vcode_test.py\", line 86, in setup_module\n    PyMySQL().mysqlinsert(\"customer_verify_email\",insert_data)\n  File \"C:\\Users\\chenping\\PycharmProjects\\apitest\\utils\\pysql.py\", line 128, in mysqlinsert\n    self.conn.commit()\n  File \"C:\\Users\\chenping\\PycharmProjects\\apitest\\venv\\lib\\site-packages\\pymysql\\connections.py\", line 420, in commit\n    self._read_ok_packet()\n  File \"C:\\Users\\chenping\\PycharmProjects\\apitest\\venv\\lib\\site-packages\\pymysql\\connections.py\", line 394, in _read_ok_packet\n    pkt = self._read_packet()\n  File \"C:\\Users\\chenping\\PycharmProjects\\apitest\\venv\\lib\\site-packages\\pymysql\\connections.py\", line 684, in _read_packet\n    packet.check_error()\n  File \"C:\\Users\\chenping\\PycharmProjects\\apitest\\venv\\lib\\site-packages\\pymysql\\protocol.py\", line 220, in check_error\n    err.raise_mysql_exception(self._data)\n  File \"C:\\Users\\chenping\\PycharmProjects\\apitest\\venv\\lib\\site-packages\\pymysql\\err.py\", line 109, in raise_mysql_exception\n    raise errorclass(errno, errval)\n"}, "start": 1619590167065, "stop": 1619590167086}, {"name": "_Module__pytest_setup_module", "status": "broken", "statusDetails": {"message": "pymysql.err.InternalError: (1003, 'Transaction error, need to rollback.')\n", "trace": "  File \"C:\\Users\\chenping\\PycharmProjects\\apitest\\venv\\lib\\site-packages\\pluggy\\callers.py\", line 187, in _multicall\n    res = hook_impl.function(*args)\n  File \"C:\\Users\\chenping\\PycharmProjects\\apitest\\venv\\lib\\site-packages\\_pytest\\fixtures.py\", line 964, in pytest_fixture_setup\n    result = call_fixture_func(fixturefunc, request, kwargs)\n  File \"C:\\Users\\chenping\\PycharmProjects\\apitest\\venv\\lib\\site-packages\\_pytest\\fixtures.py\", line 788, in call_fixture_func\n    res = next(it)\n  File \"C:\\Users\\chenping\\PycharmProjects\\apitest\\venv\\lib\\site-packages\\_pytest\\python.py\", line 471, in xunit_setup_module_fixture\n    _call_with_optional_argument(setup_module, request.module)\n  File \"C:\\Users\\chenping\\PycharmProjects\\apitest\\venv\\lib\\site-packages\\_pytest\\python.py\", line 634, in _call_with_optional_argument\n    func()\n  File \"C:\\Users\\chenping\\PycharmProjects\\apitest\\testcase\\Loginapi\\Check_Sms_Vcode_test.py\", line 86, in setup_module\n    PyMySQL().mysqlinsert(\"customer_verify_email\",insert_data)\n  File \"C:\\Users\\chenping\\PycharmProjects\\apitest\\utils\\pysql.py\", line 128, in mysqlinsert\n    self.conn.commit()\n  File \"C:\\Users\\chenping\\PycharmProjects\\apitest\\venv\\lib\\site-packages\\pymysql\\connections.py\", line 420, in commit\n    self._read_ok_packet()\n  File \"C:\\Users\\chenping\\PycharmProjects\\apitest\\venv\\lib\\site-packages\\pymysql\\connections.py\", line 394, in _read_ok_packet\n    pkt = self._read_packet()\n  File \"C:\\Users\\chenping\\PycharmProjects\\apitest\\venv\\lib\\site-packages\\pymysql\\connections.py\", line 684, in _read_packet\n    packet.check_error()\n  File \"C:\\Users\\chenping\\PycharmProjects\\apitest\\venv\\lib\\site-packages\\pymysql\\protocol.py\", line 220, in check_error\n    err.raise_mysql_exception(self._data)\n  File \"C:\\Users\\chenping\\PycharmProjects\\apitest\\venv\\lib\\site-packages\\pymysql\\err.py\", line 109, in raise_mysql_exception\n    raise errorclass(errno, errval)\n"}, "start": 1619590177527, "stop": 1619590177554}, {"name": "_Module__pytest_setup_module", "status": "broken", "statusDetails": {"message": "pymysql.err.InternalError: (1003, 'Transaction error, need to rollback.')\n", "trace": "  File \"C:\\Users\\chenping\\PycharmProjects\\apitest\\venv\\lib\\site-packages\\pluggy\\callers.py\", line 187, in _multicall\n    res = hook_impl.function(*args)\n  File \"C:\\Users\\chenping\\PycharmProjects\\apitest\\venv\\lib\\site-packages\\_pytest\\fixtures.py\", line 964, in pytest_fixture_setup\n    result = call_fixture_func(fixturefunc, request, kwargs)\n  File \"C:\\Users\\chenping\\PycharmProjects\\apitest\\venv\\lib\\site-packages\\_pytest\\fixtures.py\", line 788, in call_fixture_func\n    res = next(it)\n  File \"C:\\Users\\chenping\\PycharmProjects\\apitest\\venv\\lib\\site-packages\\_pytest\\python.py\", line 471, in xunit_setup_module_fixture\n    _call_with_optional_argument(setup_module, request.module)\n  File \"C:\\Users\\chenping\\PycharmProjects\\apitest\\venv\\lib\\site-packages\\_pytest\\python.py\", line 634, in _call_with_optional_argument\n    func()\n  File \"C:\\Users\\chenping\\PycharmProjects\\apitest\\testcase\\Loginapi\\Check_Sms_Vcode_test.py\", line 86, in setup_module\n    PyMySQL().mysqlinsert(\"customer_verify_email\",insert_data)\n  File \"C:\\Users\\chenping\\PycharmProjects\\apitest\\utils\\pysql.py\", line 128, in mysqlinsert\n    self.conn.commit()\n  File \"C:\\Users\\chenping\\PycharmProjects\\apitest\\venv\\lib\\site-packages\\pymysql\\connections.py\", line 420, in commit\n    self._read_ok_packet()\n  File \"C:\\Users\\chenping\\PycharmProjects\\apitest\\venv\\lib\\site-packages\\pymysql\\connections.py\", line 394, in _read_ok_packet\n    pkt = self._read_packet()\n  File \"C:\\Users\\chenping\\PycharmProjects\\apitest\\venv\\lib\\site-packages\\pymysql\\connections.py\", line 684, in _read_packet\n    packet.check_error()\n  File \"C:\\Users\\chenping\\PycharmProjects\\apitest\\venv\\lib\\site-packages\\pymysql\\protocol.py\", line 220, in check_error\n    err.raise_mysql_exception(self._data)\n  File \"C:\\Users\\chenping\\PycharmProjects\\apitest\\venv\\lib\\site-packages\\pymysql\\err.py\", line 109, in raise_mysql_exception\n    raise errorclass(errno, errval)\n"}, "start": 1619590187966, "stop": 1619590187989}], "start": 1619590187966, "stop": 1619590188369}